Workbook

Sheet Start Here
A1: NOVADRIVE | CLEAN RESEARCH DATA PACK
A2: Purpose-built for feeding the useful evidence and analysis into an AI dashboard builder. No duplicate dashboard, outreach tracker, or redundant summary sheets.
A3: Field | B3: Description
A4: Purpose | B4: Compact research data pack for AI/dashboard creation. Includes only core source data, derived risk assessments, event handling, and alternate supplier fitment research.
A5: How to use | B5: Use the source evidence and network relationship sheets as the traceable foundation. Use risk score sheets for prioritization. Use alternate fitment separately from supplier risk.
A6: Core deliverables represented | B6: Supplier network mapping; supplier risk scorecard; event-based risk alerts; alternate supplier assessment with public evidence; management action context embedded in component risk and alert sheets.
A7: Source data | B7: The case workbook is synthetic case data. Relationship Evidence contains evidence IDs, dates, source families, detail, record status, and locators. Public candidate evidence is in Alternate Supplier Assessment.
A8: Relationship status | B8: Confirmed = supported by relationship evidence. Inferred = reasonable but not fully established. Unresolved hypothesis = do not treat as a confirmed network link. Excluded / mismatch = do not use as supplier exposure. Excluded / mismatch items are listed in 'Excluded & Mismatches'.
A9: Allocation caveat | B9: Supplier allocations are planning/contracted allocations from case evidence, not necessarily realized purchase shares or actual deliveries.
A10: Event caveat | B10: EV-001 and EV-002 are the same flood-watch signal; count once. A flood watch does not establish damage or shutdown. EV-003 reports Meridian financing pressure while production continues. EV-004 and EV-009 are entity mismatches. EV-005 is stale. EV-007 is administrative HQ relocation. EV-010 route exposure to Estuary is unconfirmed.
A11: Risk vs fitment | B11: Supplier risk score measures vulnerability/exposure. Alternate fitment score estimates plausible capability match based on public evidence. They are different assessments and must not be combined as if they measured the same thing.
A12: Alternate candidate limitation | B12: All alternate candidates are initial public-source screens only. Scores do not establish exact interchangeability, available capacity, pricing, qualification, approval, or actual supplier willingness.
A13: Excluded operational trackers | B13: Contact logs, sample status, quotation trackers, qualification gate checklists and duplicate dashboard sheets are intentionally excluded because no actual supplier outreach/qualification has occurred and these are not required for the research deliverable.
A14: Data cut-off | B14: Event dates and source dates are those in the supplied case data and public-source research captured in the working assessment. Verify live public evidence before final external use.
... A17: Open items for the team | B17: 1) Original supplier-level weights remain undocumented; headline scores unchanged. 2) Access dates for the 14 original alternate-supplier rows are not recorded: fill the yellow cells after re-checking each URL. 3) Concentration score for M10/M20 (80) not changed despite common ownership: review. 4) PolarSwitch (DOC-078) has no public evidence. 5) Tier-2 alternates are screens; qualification runs through the Tier-1 supplier.

Sheet Business & Components
A1: BUSINESS CONTEXT
A2: Product ID | B2: Product Name | C2: Annual Revenue (USD m) | D2: Weekly Units | E2: Primary Manufacturing Footprint | F2: Management Context
A3: P1 | B3: DriveCore industrial inverter | C3: 624 | D3: 2000 | E3: Harbor Works (60%); Plateau Works (40%) | F3: Use revenue and product footprint as business-criticality context; no supplier spend is provided.
A4: P2 | B4: ChargeBridge charging power unit | C4: 520 | D4: 1000 | E4: Harbor Works (30%); Coastal Works (70%) | F4: Use revenue and product footprint as business-criticality context; no supplier spend is provided.
A5: P3 | B5: StoreLink storage control cabinet | C5: 416 | D5: 800 | E5: Plateau Works (100%) | F5: Use revenue and product footprint as business-criticality context; no supplier spend is provided.
A8: COMPONENT CONTEXT
A9: Component ID | B9: Component Name | C9: Key application | D9: Indicative supplier Qualification Lead Time (Weeks) | E9: Key Criteria for Alternate Supplier Search
A10: M10 | B10: Standard power assembly | C10: Industrial inverter power assembly; IGBT/SiC-capable module integration | D10: 16 | E10: 1. Products Using This Component: P1, P3 2. Application / Use Case: Industrial drives / power conversion 3. Supplier Screening Criteria: Search for manufacturers with comparable power-module assembly capability; technical qualification remains required.
A11: M20 | B11: High-voltage power assembly | C11: High-voltage power assembly for charging power conversion; IGBT/SiC-capable | D11: 16 | E11: 1. Products Using This Component: P2 2. Application / Use Case: EV / industrial charging power conversion 3. Supplier Screening Criteria: Assess voltage/current class, thermal design, quality systems and production scale before treating any candidate as a substitute.
A12: C10 | B12: Control board | C12: Industrial control PCB/PCBA with embedded microcontroller and power-control interfaces | D12: 12 | E12: 1. Products Using This Component: P1, P2, P3 2. Application / Use Case: Industrial electronics / power control 3. Supplier Screening Criteria: Look for design-and-manufacture capability, industrial quality systems, controller ecosystem and production footprint.
A13: C20 | B13: DC-link capacitor | C13: High-energy DC-link film capacitor for power-electronics applications | D13: 8 | E13: 1. Products Using This Component: P1, P2 2. Application / Use Case: Inverters / power conversion 3. Supplier Screening Criteria: Fit depends on electrical, thermal, lifetime and packaging requirements; public similarity is only an initial screen.
A14: H10 | B14: Protective housing | C14: Machined/fabricated aluminum enclosure for industrial power electronics | D14: 4 | E14: 1. Products Using This Component: P1 2. Application / Use Case: Industrial electronics enclosure 3. Supplier Screening Criteria: Assess material, tolerance, environmental protection, tooling and regional manufacturing capability.
A15: H20 | B15: Cooling assembly | C15: Thermal-management / liquid-cooling assembly for power electronics | D15: 6 | E15: 1. Products Using This Component: P2, P3 2. Application / Use Case: Power electronics thermal management 3. Supplier Screening Criteria: Assess thermal performance, materials, leak/reliability testing, scale and geographic suitability.
A16: B10 | B16: Battery-monitoring board | C16: Battery-monitoring/control PCBA with sensing and embedded electronics | D16: 12 | E16: 1. Products Using This Component: P3 2. Application / Use Case: Battery systems / energy storage electronics 3. Supplier Screening Criteria: Assess battery-control experience, electronics manufacturing capability, safety/quality systems and production scale.

Sheet Supplier Universe & Risk
A1: SUPPLIER UNIVERSE + INDICATORS + RISK
A2: One row per entity from the case Supplier Universe, enriched with raw business indicators and available supplier risk score/category. Blank score means no mapped supplier score was assigned.
A3: Entity ID | B3: Legal Name | C3: Entity Type | D3: Public Capability | E3: Registered Market | F3: Registered Zone | G3: Primary Facility ID | H3: Primary Facility Name | I3: Facility Zone | J3: Facility Role | K3: Facility Capability | L3: Other Known Site / Note | M3: Current Ratio | N3: Net Debt / EBITDA | O3: Shipment Timeliness - 3M Avg (%) | P3: Timeliness Change - Jan To Latest (pp) | Q3: Assurance Gap Index | R3: Physical Hazard Index | S3: Logistics Friction Index | T3: Infrastructure Index | U3: Supplier Risk Score | V3: Supplier Risk Category | W3: Risk Data Completeness | X3: Relationship Confidence | Y3: Risk Notes
A4: ORG-247 | B4: Aster Power Assemblies Ltd. | C4: Manufacturer | D4: Power assemblies M10/M20 | E4: Norland | F4: Z02 | G4: SITE-018 | H4: Aster Works | I4: Z02 | J4: Manufacturing | K4: Power assemblies M10/M20 | M4: 2.13 | N4: 2 | O4: 80.9 | P4: 2.3 | Q4: 24 | R4: 27 | S4: 30 | T4: 24 | U4: 51.8 | V4: MEDIUM | W4: High | X4: Confirmed
A5: ORG-725 | B5: Boreal Power Systems Ltd. | C5: Manufacturer | D5: Power assemblies M10/M20 | E5: Westmere | F5: Z05 | G5: SITE-025 | H5: Boreal Works | I5: Z05 | J5: Manufacturing | K5: Power assemblies M10/M20 | M5: 1.54 | N5: 3 | O5: 83.1 | P5: 2.2 | Q5: 33 | R5: 31 | S5: 23 | T5: 19 | U5: 52.7 | V5: MEDIUM | W5: High | X5: Confirmed
A6: ORG-119 | B6: Cobalt Control Electronics Ltd. | C6: Manufacturer | D6: Control board C10 | E6: Estara | F6: Z04 | G6: SITE-032 | H6: Cobalt Works | I6: Z04 | J6: Manufacturing | K6: Control board C10 | M6: 2.34 | N6: 4 | O6: 83.3 | P6: -2.3 | Q6: 42 | R6: 58 | S6: 62 | T6: 52 | U6: 69 | V6: HIGH | W6: High | X6: Confirmed
A7: ORG-268 | B7: CommonSpan Holdings Ltd. | C7: Holding company | D7: Holding company | E7: Westmere | F7: Z05 | G7: SITE-221 | H7: CommonSpan Works | I7: Z05 | J7: Office or service | K7: Holding company | M7: 2.04 | N7: 1 | O7: 87.6 | P7: -1.1 | Q7: 45 | R7: 31 | S7: 23 | T7: 19
A8: ORG-922 | B8: Delta Capacitor Works Ltd. | C8: Manufacturer | D8: Capacitor C20 | E8: Westmere | F8: Z03 | G8: SITE-039 | H8: Delta Works | I8: Z03 | J8: Manufacturing | K8: Capacitor C20 | M8: 1.82 | N8: 1.67 | O8: 86.9 | P8: 2.2 | Q8: 51 | R8: 19 | S8: 26 | T8: 25 | U8: 49.7 | V8: MEDIUM | W8: High | X8: Confirmed
A9: ORG-857 | B9: Delta Consumer Plastics Ltd. | C9: Manufacturer | D9: Consumer packaging | E9: Norland | F9: Z02 | G9: SITE-249 | H9: Delta Works | I9: Z02 | J9: Manufacturing | K9: Consumer packaging | O9: 83.7 | P9: 2.2 | R9: 27 | S9: 30 | T9: 24
A10: ORG-786 | B10: Estuary Thermal Systems Ltd. | C10: Manufacturer | D10: Cooling assembly H20 | E10: Talora | F10: Z06 | G10: SITE-046 | H10: Estuary Works | I10: Z06 | J10: Manufacturing | K10: Cooling assembly H20 | M10: 2.53 | N10: 2.67 | O10: 89.7 | P10: 1.8 | Q10: 60 | R10: 67 | S10: 59 | T10: 54 | U10: 48.4 | V10: MEDIUM | W10: High | X10: Confirmed
A11: ORG-287 | B11: ForgeLine Enclosures Ltd. | C11: Manufacturer | D11: Housing H10 | E11: Norland | F11: Z02 | G11: SITE-053 | H11: ForgeLine Works | I11: Z02 | J11: Manufacturing | K11: Housing H10 | M11: 1.94 | N11: 3.67 | O11: 89.8 | P11: -0.3 | Q11: 69 | R11: 27 | S11: 30 | T11: 24 | U11: 45.4 | V11: MEDIUM | W11: High | X11: Confirmed
A12: ORG-103 | B12: Grove Battery Controls Ltd. | C12: Manufacturer | D12: Battery monitor B10 | E12: Estara | F12: Z04 | G12: SITE-060 | H12: Grove Works | I12: Z04 | J12: Manufacturing | K12: Battery monitor B10 | M12: 1.51 | N12: 1.33 | O12: 78.8 | P12: -0.9 | Q12: 18 | R12: 58 | S12: 62 | T12: 52 | U12: 44.6 | V12: LOW | W12: High | X12: Confirmed
A13: ORG-328 | B13: Harbor Freight Services Ltd. | C13: Logistics or intermediary | D13: Freight forwarding | E13: Norland | F13: Z07 | G13: SITE-242 | H13: Harbor Works | I13: Z07 | J13: Office or service | K13: Freight forwarding | M13: 1.68 | N13: 4 | O13: 80.6 | P13: 1.4 | Q13: 72 | R13: 34 | S13: 36 | T13: 30
A14: ORG-176 | B14: HarborSense Electronics Ltd. | C14: Manufacturer | D14: Battery monitor B10 | E14: Westmere | F14: Z05 | G14: SITE-067 | H14: HarborSense Works | I14: Z05 | J14: Manufacturing | K14: Battery monitor B10 | M14: 2.24 | N14: 2.33 | O14: 81.9 | P14: -0.9 | Q14: 27 | R14: 31 | S14: 23 | T14: 19 | U14: 32.5 | V14: LOW | W14: High | X14: Confirmed
A15: ORG-309 | B15: Ion Peak Trading Ltd. | C15: Logistics or intermediary | D15: Trade brokerage | E15: Norland | F15: Z07 | G15: SITE-207 | H15: Ion Works | I15: Z07 | J15: Office or service | K15: Trade brokerage | O15: 82.7 | P15: 2.8 | R15: 34 | S15: 36 | T15: 30
A16: ORG-439 | B16: IonPeak Semiconductor Ltd. | C16: Manufacturer | D16: Power semiconductor dies | E16: Estara | F16: Z01 | G16: SITE-074 | H16: IonPeak Works | I16: Z01 | J16: Manufacturing | K16: Power semiconductor dies | L16: SITE-900 - IonPeak Western Development Center (Research and pilot line, Z05) | M16: 1.8 | N16: 2.4 | O16: 85.2 | P16: -8.8 | Q16: 36 | R16: 82 | S16: 76 | T16: 71 | U16: 79 | V16: CRITICAL | W16: High | X16: Confirmed
A17: ORG-445 | B17: Jade Circuits Holdings Ltd. | C17: Holding company | D17: Holding company | E17: Norland | F17: Z07 | G17: SITE-214 | H17: Jade Works | I17: Z07 | J17: Office or service | K17: Holding company | M17: 2.46 | N17: 3.33 | O17: 85.4 | P17: -0.6 | Q17: 36 | R17: 34 | S17: 36 | T17: 30
A18: ORG-453 | B18: Jade Printed Circuits Ltd. | C18: Manufacturer | D18: Printed circuit substrates | E18: Estara | F18: Z01 | G18: SITE-081 | H18: Jade Works | I18: Z01 | J18: Manufacturing | K18: Printed circuit substrates | L18: SITE-901 - Jade Corporate Office (Headquarters only, Z07) | M18: 1.55 | N18: 3.1 | O18: 86.6 | P18: -6.4 | Q18: 45 | R18: 82 | S18: 76 | T18: 71 | U18: 79 | V18: CRITICAL | W18: High | X18: Confirmed
A19: ORG-728 | B19: Kestrel Microdevices Ltd. | C19: Manufacturer | D19: Microcontrollers | E19: Westmere | F19: Z05 | G19: SITE-088 | H19: Kestrel Works | I19: Z05 | J19: Manufacturing | K19: Microcontrollers | M19: 1.86 | N19: 2 | O19: 87.3 | P19: 1.6 | Q19: 54 | R19: 31 | S19: 23 | T19: 19 | U19: 57.2 | V19: MEDIUM | W19: High | X19: Confirmed
A20: ORG-942 | B20: Lumen Magnetics Ltd. | C20: Manufacturer | D20: Magnetic cores | E20: Estara | F20: Z04 | G20: SITE-095 | H20: Lumen Works | I20: Z04 | J20: Manufacturing | K20: Magnetic cores | M20: 1.37 | N20: 3 | O20: 89.5 | P20: -0.6 | Q20: 63 | R20: 58 | S20: 62 | T20: 52 | U20: 69.4 | V20: HIGH | W20: High | X20: Confirmed
A21: ORG-210 | B21: Meridian Dielectrics Ltd. | C21: Manufacturer | D21: Dielectric film | E21: Westmere | F21: Z03 | G21: SITE-102 | H21: Meridian Works | I21: Z03 | J21: Manufacturing | K21: Dielectric film | M21: 0.62 | N21: 7.2 | O21: 76.4 | P21: -17.6 | Q21: 72 | R21: 19 | S21: 26 | T21: 25 | U21: 83.7 | V21: CRITICAL | W21: High | X21: Confirmed
A22: ORG-849 | B22: Nacre Foils Ltd. | C22: Manufacturer | D22: Aluminum foil | E22: Talora | F22: Z06 | G22: SITE-109 | H22: Nacre Works | I22: Z06 | J22: Manufacturing | K22: Aluminum foil | M22: 1.54 | N22: 1.67 | O22: 79.3 | P22: -3.5 | Q22: 21 | R22: 67 | S22: 59 | T22: 54 | U22: 61.7 | V22: HIGH | W22: High | X22: Confirmed
A23: ORG-708 | B23: Orion Ceramics Ltd. | C23: Manufacturer | D23: Ceramic substrates | E23: Estara | F23: Z01 | G23: SITE-116 | H23: Orion Works | I23: Z01 | J23: Manufacturing | K23: Ceramic substrates | M23: 2.29 | N23: 2.67 | O23: 82.2 | P23: 0.7 | Q23: 30 | R23: 82 | S23: 76 | T23: 71 | U23: 68.8 | V23: HIGH | W23: High | X23: Confirmed
A24: ORG-274 | B24: Pine Thermal Metals Ltd. | C24: Manufacturer | D24: Thermal metals | E24: Talora | F24: Z06 | G24: SITE-123 | H24: Pine Works | I24: Z06 | J24: Manufacturing | K24: Thermal metals | M24: 1.79 | N24: 3.67 | O24: 85.6 | P24: 0.8 | Q24: 39 | R24: 67 | S24: 59 | T24: 54 | U24: 57.3 | V24: MEDIUM | W24: High | X24: Confirmed
A25: ORG-329 | B25: Quartz Alloy Ltd. | C25: Manufacturer | D25: Aluminum alloy | E25: Norland | F25: Z02 | G25: SITE-130 | H25: Quartz Works | I25: Z02 | J25: Manufacturing | K25: Aluminum alloy | M25: 2.43 | N25: 1.33 | O25: 84.6 | P25: -2.1 | Q25: 48 | R25: 27 | S25: 30 | T25: 24 | U25: 39.3 | V25: LOW | W25: High | X25: Confirmed
A26: ORG-469 | B26: Rill Connectors Ltd. | C26: Manufacturer | D26: Connectors | E26: Estara | F26: Z04 | G26: SITE-137 | H26: Rill Works | I26: Z04 | J26: Manufacturing | K26: Connectors | M26: 2.04 | N26: 2.33 | O26: 89.3 | P26: 0.3 | Q26: 57 | R26: 58 | S26: 62 | T26: 52 | U26: 60.9 | V26: HIGH | W26: High | X26: Confirmed
A27: ORG-320 | B27: Solace Optics Ltd. | C27: Manufacturer | D27: Isolation optics | E27: Talora | F27: Z08 | G27: SITE-144 | H27: Solace Works | I27: Z08 | J27: Manufacturing | K27: Isolation optics | O27: 91.7 | P27: -0.3 | R27: 39 | S27: 47 | T27: 41
A28: ORG-455 | B28: Umber Silicon Carbide Ltd. | C28: Manufacturer | D28: Silicon-carbide wafers | E28: Estara | F28: Z01 | G28: SITE-158 | H28: Umber Works | I28: Z01 | J28: Manufacturing | K28: Silicon-carbide wafers | O28: 80.5 | P28: -2.2 | R28: 82 | S28: 76 | T28: 71 | U28: 74.4 | V28: HIGH | W28: Medium | X28: Confirmed | Y28: Tier-3 link via IonPeak (confirmed). Financial and assurance indicators are blank in the case data, so this score is provisional; missing information is not treated as low risk (see 'Supplier Score Build').
A29: ORG-736 | B29: Verdant Process Gases Ltd. | C29: Manufacturer | D29: Process gases | E29: Estara | F29: Z01 | G29: SITE-165 | H29: Verdant Works | I29: Z01 | J29: Manufacturing | K29: Process gases | O29: 81.9 | P29: -0.9 | R29: 82 | S29: 76 | T29: 71 | U29: 73.4 | V29: HIGH | W29: Medium | X29: Inference | Y29: Tier-3 link to IonPeak is an inference, not a confirmed relationship. Financial and assurance indicators are blank in the case data, so this score is provisional; missing information is not treated as low risk (see 'Supplier Score Build').
A30: ORG-873 | B30: Warden Copper Foil Ltd. | C30: Manufacturer | D30: Copper foil | E30: Talora | F30: Z06 | G30: SITE-172 | H30: Warden Works | I30: Z06 | J30: Manufacturing | K30: Copper foil | O30: 87.4 | P30: 1.8 | R30: 67 | S30: 59 | T30: 54 | U30: 64.9 | V30: HIGH | W30: Medium | X30: Confirmed | Y30: Tier-3 link via Jade. Financial and assurance indicators are blank in the case data, so this score is provisional; missing information is not treated as low risk (see 'Supplier Score Build').
A31: ORG-179 | B31: Xenon Resin Ltd. | C31: Manufacturer | D31: Resin | E31: Estara | F31: Z04 | G31: SITE-179 | H31: Xenon Works | I31: Z04 | J31: Manufacturing | K31: Resin | O31: 87.3 | P31: 1.8 | R31: 58 | S31: 62 | T31: 52 | U31: 64.4 | V31: HIGH | W31: Medium | X31: Confirmed | Y31: Tier-3 link via Jade. Financial and assurance indicators are blank in the case data, so this score is provisional; missing information is not treated as low risk (see 'Supplier Score Build').
A32: ORG-520 | B32: Yarrow Specialty Minerals Ltd. | C32: Manufacturer | D32: Specialty minerals | E32: Talora | F32: Z08 | G32: SITE-186 | H32: Yarrow Works | I32: Z08 | J32: Manufacturing | K32: Specialty minerals | O32: 90.1 | P32: -1.2 | R32: 39 | S32: 47 | T32: 41 | U32: 63.5 | V32: HIGH | W32: Medium | X32: Confirmed | Y32: Tier-3 link via Orion. Financial and assurance indicators are blank in the case data, so this score is provisional; missing information is not treated as low risk (see 'Supplier Score Build').
A33: ORG-659 | B33: Zenith Polymer Ltd. | C33: Manufacturer | D33: Polymer | E33: Westmere | F33: Z03 | G33: SITE-193 | H33: Zenith Works | I33: Z03 | J33: Manufacturing | K33: Polymer | O33: 90.9 | P33: -0.9 | R33: 19 | S33: 26 | T33: 25 | U33: 51.6 | V33: MEDIUM | W33: Medium | X33: Confirmed | Y33: Tier-3 link via Meridian. Financial and assurance indicators are blank in the case data, so this score is provisional; missing information is not treated as low risk (see 'Supplier Score Build').

Sheet Supplier Score Build
A1: SUPPLIER SCORE BUILD (explainable cross-check of the headline supplier risk score)
A2: The original supplier-level weights are not documented in the source files and could not be reproduced from the eight raw indicators. This sheet rebuilds an INTRINSIC supplier-condition score from those indicators with stated, editable weights (blue cells). It does not replace the headline score; it shows what the indicators alone explain, and the gap is the part driven by other factors (likely criticality, concentration, network dependence - confirm with the original scorer). Missing pillars default to a prudent 60, never to low risk.
A4: Parameter | B4: Value | C4: Note
A5: Weight - Financial pillar | B5: 0.3 | C5: Current ratio and Net Debt/EBITDA
A6: Weight - Operational pillar | B6: 0.25 | C6: Shipment timeliness level and Jan-to-latest change
A7: Weight - Location pillar | B7: 0.3 | C7: Average of Physical Hazard, Logistics Friction and Infrastructure indices (already 0-100)
A8: Weight - Assurance pillar | B8: 0.15 | C8: Assurance Gap Index (0-100)
A9: Weights check (must equal 1) | B9: =SUM(B5:B8) -> 1 | C9: Formula
A10: Current ratio - best (0 risk) | B10: 2.5 | C10: Assumption; at or above this scores 0
A11: Current ratio - worst (100 risk) | B11: 0.8 | C11: Assumption; at or below this scores 100
A12: Net Debt/EBITDA - best (0 risk) | B12: 1 | C12: Assumption
A13: Net Debt/EBITDA - worst (100 risk) | B13: 7 | C13: Assumption
A14: Timeliness % - best (0 risk) | B14: 92 | C14: Assumption
A15: Timeliness % - worst (100 risk) | B15: 76 | C15: Assumption
A16: Timeliness change pp - best (0 risk) | B16: 3 | C16: Assumption
A17: Timeliness change pp - worst (100 risk) | B17: -18 | C17: Assumption
A18: Missing-pillar default score | B18: 60 | C18: Missing information is NOT treated as low risk; a blank pillar takes this value and is flagged
A20: Legend: blue = editable assumption; green = pulled from another sheet; black = formula. Weights and anchors are analyst assumptions for transparency, not values from the case.
A22: Entity ID | B22: Legal Name | C22: Current Ratio | D22: Net Debt / EBITDA | E22: Timeliness 3M Avg (%) | F22: Timeliness Change (pp) | G22: Assurance Gap Index | H22: Physical Hazard Index | I22: Logistics Friction Index | J22: Infrastructure Index | K22: Financial pillar (0-100) | L22: Operational pillar (0-100) | M22: Location pillar (0-100) | N22: Assurance pillar (0-100) | O22: Missing pillars (count) | P22: Data completeness | Q22: Intrinsic indicator score | R22: Headline supplier risk score | S22: Headline risk band | T22: Gap: headline minus intrinsic | U22: Rank - headline | V22: Rank - intrinsic
A23: ORG-247 | B23: Aster Power Assemblies Ltd. | C23: =IF(INDEX('Supplier Universe & Risk'!$M$4:$M$33,MATCH($A23,'Supplier Universe & Risk'!$A$4:$A$33,0))="","",INDEX('Supplier Universe & Risk'!$M$4:$M$33,MATCH($A23,'Supplier Universe & Risk'!$A$4:$A$33,0))) -> 2.13 | D23: =IF(INDEX('Supplier Universe & Risk'!$N$4:$N$33,MATCH($A23,'Supplier Universe & Risk'!$A$4:$A$33,0))="","",INDEX('Supplier Universe & Risk'!$N$4:$N$33,MATCH($A23,'Supplier Universe & Risk'!$A$4:$A$33,0))) -> 2 | E23: =IF(INDEX('Supplier Universe & Risk'!$O$4:$O$33,MATCH($A23,'Supplier Universe & Risk'!$A$4:$A$33,0))="","",INDEX('Supplier Universe & Risk'!$O$4:$O$33,MATCH($A23,'Supplier Universe & Risk'!$A$4:$A$33,0))) -> 80.9 | F23: =IF(INDEX('Supplier Universe & Risk'!$P$4:$P$33,MATCH($A23,'Supplier Universe & Risk'!$A$4:$A$33,0))="","",INDEX('Supplier Universe & Risk'!$P$4:$P$33,MATCH($A23,'Supplier Universe & Risk'!$A$4:$A$33,0))) -> 2.3 | G23: =IF(INDEX('Supplier Universe & Risk'!$Q$4:$Q$33,MATCH($A23,'Supplier Universe & Risk'!$A$4:$A$33,0))="","",INDEX('Supplier Universe & Risk'!$Q$4:$Q$33,MATCH($A23,'Supplier Universe & Risk'!$A$4:$A$33,0))) -> 24 | H23: =IF(INDEX('Supplier Universe & Risk'!$R$4:$R$33,MATCH($A23,'Supplier Universe & Risk'!$A$4:$A$33,0))="","",INDEX('Supplier Universe & Risk'!$R$4:$R$33,MATCH($A23,'Supplier Universe & Risk'!$A$4:$A$33,0))) -> 27 | I23: =IF(INDEX('Supplier Universe & Risk'!$S$4:$S$33,MATCH($A23,'Supplier Universe & Risk'!$A$4:$A$33,0))="","",INDEX('Supplier Universe & Risk'!$S$4:$S$33,MATCH($A23,'Supplier Universe & Risk'!$A$4:$A$33,0))) -> 30 | J23: =IF(INDEX('Supplier Universe & Risk'!$T$4:$T$33,MATCH($A23,'Supplier Universe & Risk'!$A$4:$A$33,0))="","",INDEX('Supplier Universe & Risk'!$T$4:$T$33,MATCH($A23,'Supplier Universe & Risk'!$A$4:$A$33,0))) -> 24 | K23: =IF(OR(C23="",D23=""),"",(MAX(0,MIN(1,($B$10-C23)/($B$10-$B$11)))*100+MAX(0,MIN(1,(D23-$B$12)/($B$13-$B$12)))*100)/2) -> 19.215686 | L23: =IF(OR(E23="",F23=""),"",(MAX(0,MIN(1,($B$14-E23)/($B$14-$B$15)))*100+MAX(0,MIN(1,($B$16-F23)/($B$16-$B$17)))*100)/2) -> 36.354167 | M23: =IF(COUNT(H23:J23)=3,AVERAGE(H23:J23),"") -> 27 | N23: =IF(G23="","",G23) -> 24 | O23: =(K23="")+(L23="")+(M23="")+(N23="") -> 0 | P23: =IF(O23=0,"Complete",IF(O23=1,"Partial - 1 pillar defaulted","Limited - "&O23&" pillars defaulted")) -> Complete | Q23: =$B$5*IF(K23="",$B$18,K23)+$B$6*IF(L23="",$B$18,L23)+$B$7*IF(M23="",$B$18,M23)+$B$8*IF(N23="",$B$18,N23) -> 26.553248 | R23: =IF(INDEX('Supplier Universe & Risk'!$U$4:$U$33,MATCH($A23,'Supplier Universe & Risk'!$A$4:$A$33,0))="","",INDEX('Supplier Universe & Risk'!$U$4:$U$33,MATCH($A23,'Supplier Universe & Risk'!$A$4:$A$33,0))) -> 51.8 | S23: =IF(INDEX('Supplier Universe & Risk'!$V$4:$V$33,MATCH($A23,'Supplier Universe & Risk'!$A$4:$A$33,0))="","",INDEX('Supplier Universe & Risk'!$V$4:$V$33,MATCH($A23,'Supplier Universe & Risk'!$A$4:$A$33,0))) -> MEDIUM | T23: =R23-Q23 -> 25.246752 | U23: =RANK(R23,$R$23:$R$46) -> 17 | V23: =RANK(Q23,$Q$23:$Q$46) -> 23
A24: ORG-725 | B24: Boreal Power Systems Ltd. | C24: =IF(INDEX('Supplier Universe & Risk'!$M$4:$M$33,MATCH($A24,'Supplier Universe & Risk'!$A$4:$A$33,0))="","",INDEX('Supplier Universe & Risk'!$M$4:$M$33,MATCH($A24,'Supplier Universe & Risk'!$A$4:$A$33,0))) -> 1.54 | D24: =IF(INDEX('Supplier Universe & Risk'!$N$4:$N$33,MATCH($A24,'Supplier Universe & Risk'!$A$4:$A$33,0))="","",INDEX('Supplier Universe & Risk'!$N$4:$N$33,MATCH($A24,'Supplier Universe & Risk'!$A$4:$A$33,0))) -> 3 | E24: =IF(INDEX('Supplier Universe & Risk'!$O$4:$O$33,MATCH($A24,'Supplier Universe & Risk'!$A$4:$A$33,0))="","",INDEX('Supplier Universe & Risk'!$O$4:$O$33,MATCH($A24,'Supplier Universe & Risk'!$A$4:$A$33,0))) -> 83.1 | F24: =IF(INDEX('Supplier Universe & Risk'!$P$4:$P$33,MATCH($A24,'Supplier Universe & Risk'!$A$4:$A$33,0))="","",INDEX('Supplier Universe & Risk'!$P$4:$P$33,MATCH($A24,'Supplier Universe & Risk'!$A$4:$A$33,0))) -> 2.2 | G24: =IF(INDEX('Supplier Universe & Risk'!$Q$4:$Q$33,MATCH($A24,'Supplier Universe & Risk'!$A$4:$A$33,0))="","",INDEX('Supplier Universe & Risk'!$Q$4:$Q$33,MATCH($A24,'Supplier Universe & Risk'!$A$4:$A$33,0))) -> 33 | H24: =IF(INDEX('Supplier Universe & Risk'!$R$4:$R$33,MATCH($A24,'Supplier Universe & Risk'!$A$4:$A$33,0))="","",INDEX('Supplier Universe & Risk'!$R$4:$R$33,MATCH($A24,'Supplier Universe & Risk'!$A$4:$A$33,0))) -> 31 | I24: =IF(INDEX('Supplier Universe & Risk'!$S$4:$S$33,MATCH($A24,'Supplier Universe & Risk'!$A$4:$A$33,0))="","",INDEX('Supplier Universe & Risk'!$S$4:$S$33,MATCH($A24,'Supplier Universe & Risk'!$A$4:$A$33,0))) -> 23 | J24: =IF(INDEX('Supplier Universe & Risk'!$T$4:$T$33,MATCH($A24,'Supplier Universe & Risk'!$A$4:$A$33,0))="","",INDEX('Supplier Universe & Risk'!$T$4:$T$33,MATCH($A24,'Supplier Universe & Risk'!$A$4:$A$33,0))) -> 19 | K24: =IF(OR(C24="",D24=""),"",(MAX(0,MIN(1,($B$10-C24)/($B$10-$B$11)))*100+MAX(0,MIN(1,(D24-$B$12)/($B$13-$B$12)))*100)/2) -> 44.901961 | L24: =IF(OR(E24="",F24=""),"",(MAX(0,MIN(1,($B$14-E24)/($B$14-$B$15)))*100+MAX(0,MIN(1,($B$16-F24)/($B$16-$B$17)))*100)/2) -> 29.717262 | M24: =IF(COUNT(H24:J24)=3,AVERAGE(H24:J24),"") -> 24.333333 | N24: =IF(G24="","",G24) -> 33 | O24: =(K24="")+(L24="")+(M24="")+(N24="") -> 0 | P24: =IF(O24=0,"Complete",IF(O24=1,"Partial - 1 pillar defaulted","Limited - "&O24&" pillars defaulted")) -> Complete | Q24: =$B$5*IF(K24="",$B$18,K24)+$B$6*IF(L24="",$B$18,L24)+$B$7*IF(M24="",$B$18,M24)+$B$8*IF(N24="",$B$18,N24) -> 33.149904 | R24: =IF(INDEX('Supplier Universe & Risk'!$U$4:$U$33,MATCH($A24,'Supplier Universe & Risk'!$A$4:$A$33,0))="","",INDEX('Supplier Universe & Risk'!$U$4:$U$33,MATCH($A24,'Supplier Universe & Risk'!$A$4:$A$33,0))) -> 52.7 | S24: =IF(INDEX('Supplier Universe & Risk'!$V$4:$V$33,MATCH($A24,'Supplier Universe & Risk'!$A$4:$A$33,0))="","",INDEX('Supplier Universe & Risk'!$V$4:$V$33,MATCH($A24,'Supplier Universe & Risk'!$A$4:$A$33,0))) -> MEDIUM | T24: =R24-Q24 -> 19.550096 | U24: =RANK(R24,$R$23:$R$46) -> 16 | V24: =RANK(Q24,$Q$23:$Q$46) -> 19
A25: ORG-119 | B25: Cobalt Control Electronics Ltd. | C25: =IF(INDEX('Supplier Universe & Risk'!$M$4:$M$33,MATCH($A25,'Supplier Universe & Risk'!$A$4:$A$33,0))="","",INDEX('Supplier Universe & Risk'!$M$4:$M$33,MATCH($A25,'Supplier Universe & Risk'!$A$4:$A$33,0))) -> 2.34 | D25: =IF(INDEX('Supplier Universe & Risk'!$N$4:$N$33,MATCH($A25,'Supplier Universe & Risk'!$A$4:$A$33,0))="","",INDEX('Supplier Universe & Risk'!$N$4:$N$33,MATCH($A25,'Supplier Universe & Risk'!$A$4:$A$33,0))) -> 4 | E25: =IF(INDEX('Supplier Universe & Risk'!$O$4:$O$33,MATCH($A25,'Supplier Universe & Risk'!$A$4:$A$33,0))="","",INDEX('Supplier Universe & Risk'!$O$4:$O$33,MATCH($A25,'Supplier Universe & Risk'!$A$4:$A$33,0))) -> 83.3 | F25: =IF(INDEX('Supplier Universe & Risk'!$P$4:$P$33,MATCH($A25,'Supplier Universe & Risk'!$A$4:$A$33,0))="","",INDEX('Supplier Universe & Risk'!$P$4:$P$33,MATCH($A25,'Supplier Universe & Risk'!$A$4:$A$33,0))) -> -2.3 | G25: =IF(INDEX('Supplier Universe & Risk'!$Q$4:$Q$33,MATCH($A25,'Supplier Universe & Risk'!$A$4:$A$33,0))="","",INDEX('Supplier Universe & Risk'!$Q$4:$Q$33,MATCH($A25,'Supplier Universe & Risk'!$A$4:$A$33,0))) -> 42 | H25: =IF(INDEX('Supplier Universe & Risk'!$R$4:$R$33,MATCH($A25,'Supplier Universe & Risk'!$A$4:$A$33,0))="","",INDEX('Supplier Universe & Risk'!$R$4:$R$33,MATCH($A25,'Supplier Universe & Risk'!$A$4:$A$33,0))) -> 58 | I25: =IF(INDEX('Supplier Universe & Risk'!$S$4:$S$33,MATCH($A25,'Supplier Universe & Risk'!$A$4:$A$33,0))="","",INDEX('Supplier Universe & Risk'!$S$4:$S$33,MATCH($A25,'Supplier Universe & Risk'!$A$4:$A$33,0))) -> 62 | J25: =IF(INDEX('Supplier Universe & Risk'!$T$4:$T$33,MATCH($A25,'Supplier Universe & Risk'!$A$4:$A$33,0))="","",INDEX('Supplier Universe & Risk'!$T$4:$T$33,MATCH($A25,'Supplier Universe & Risk'!$A$4:$A$33,0))) -> 52 | K25: =IF(OR(C25="",D25=""),"",(MAX(0,MIN(1,($B$10-C25)/($B$10-$B$11)))*100+MAX(0,MIN(1,(D25-$B$12)/($B$13-$B$12)))*100)/2) -> 29.705882 | L25: =IF(OR(E25="",F25=""),"",(MAX(0,MIN(1,($B$14-E25)/($B$14-$B$15)))*100+MAX(0,MIN(1,($B$16-F25)/($B$16-$B$17)))*100)/2) -> 39.806548 | M25: =IF(COUNT(H25:J25)=3,AVERAGE(H25:J25),"") -> 57.333333 | N25: =IF(G25="","",G25) -> 42 | O25: =(K25="")+(L25="")+(M25="")+(N25="") -> 0 | P25: =IF(O25=0,"Complete",IF(O25=1,"Partial - 1 pillar defaulted","Limited - "&O25&" pillars defaulted")) -> Complete | Q25: =$B$5*IF(K25="",$B$18,K25)+$B$6*IF(L25="",$B$18,L25)+$B$7*IF(M25="",$B$18,M25)+$B$8*IF(N25="",$B$18,N25) -> 42.363402 | R25: =IF(INDEX('Supplier Universe & Risk'!$U$4:$U$33,MATCH($A25,'Supplier Universe & Risk'!$A$4:$A$33,0))="","",INDEX('Supplier Universe & Risk'!$U$4:$U$33,MATCH($A25,'Supplier Universe & Risk'!$A$4:$A$33,0))) -> 69 | S25: =IF(INDEX('Supplier Universe & Risk'!$V$4:$V$33,MATCH($A25,'Supplier Universe & Risk'!$A$4:$A$33,0))="","",INDEX('Supplier Universe & Risk'!$V$4:$V$33,MATCH($A25,'Supplier Universe & Risk'!$A$4:$A$33,0))) -> HIGH | T25: =R25-Q25 -> 26.636598 | U25: =RANK(R25,$R$23:$R$46) -> 7 | V25: =RANK(Q25,$Q$23:$Q$46) -> 13
A26: ORG-922 | B26: Delta Capacitor Works Ltd. | C26: =IF(INDEX('Supplier Universe & Risk'!$M$4:$M$33,MATCH($A26,'Supplier Universe & Risk'!$A$4:$A$33,0))="","",INDEX('Supplier Universe & Risk'!$M$4:$M$33,MATCH($A26,'Supplier Universe & Risk'!$A$4:$A$33,0))) -> 1.82 | D26: =IF(INDEX('Supplier Universe & Risk'!$N$4:$N$33,MATCH($A26,'Supplier Universe & Risk'!$A$4:$A$33,0))="","",INDEX('Supplier Universe & Risk'!$N$4:$N$33,MATCH($A26,'Supplier Universe & Risk'!$A$4:$A$33,0))) -> 1.67 | E26: =IF(INDEX('Supplier Universe & Risk'!$O$4:$O$33,MATCH($A26,'Supplier Universe & Risk'!$A$4:$A$33,0))="","",INDEX('Supplier Universe & Risk'!$O$4:$O$33,MATCH($A26,'Supplier Universe & Risk'!$A$4:$A$33,0))) -> 86.9 | F26: =IF(INDEX('Supplier Universe & Risk'!$P$4:$P$33,MATCH($A26,'Supplier Universe & Risk'!$A$4:$A$33,0))="","",INDEX('Supplier Universe & Risk'!$P$4:$P$33,MATCH($A26,'Supplier Universe & Risk'!$A$4:$A$33,0))) -> 2.2 | G26: =IF(INDEX('Supplier Universe & Risk'!$Q$4:$Q$33,MATCH($A26,'Supplier Universe & Risk'!$A$4:$A$33,0))="","",INDEX('Supplier Universe & Risk'!$Q$4:$Q$33,MATCH($A26,'Supplier Universe & Risk'!$A$4:$A$33,0))) -> 51 | H26: =IF(INDEX('Supplier Universe & Risk'!$R$4:$R$33,MATCH($A26,'Supplier Universe & Risk'!$A$4:$A$33,0))="","",INDEX('Supplier Universe & Risk'!$R$4:$R$33,MATCH($A26,'Supplier Universe & Risk'!$A$4:$A$33,0))) -> 19 | I26: =IF(INDEX('Supplier Universe & Risk'!$S$4:$S$33,MATCH($A26,'Supplier Universe & Risk'!$A$4:$A$33,0))="","",INDEX('Supplier Universe & Risk'!$S$4:$S$33,MATCH($A26,'Supplier Universe & Risk'!$A$4:$A$33,0))) -> 26 | J26: =IF(INDEX('Supplier Universe & Risk'!$T$4:$T$33,MATCH($A26,'Supplier Universe & Risk'!$A$4:$A$33,0))="","",INDEX('Supplier Universe & Risk'!$T$4:$T$33,MATCH($A26,'Supplier Universe & Risk'!$A$4:$A$33,0))) -> 25 | K26: =IF(OR(C26="",D26=""),"",(MAX(0,MIN(1,($B$10-C26)/($B$10-$B$11)))*100+MAX(0,MIN(1,(D26-$B$12)/($B$13-$B$12)))*100)/2) -> 25.583333 | L26: =IF(OR(E26="",F26=""),"",(MAX(0,MIN(1,($B$14-E26)/($B$14-$B$15)))*100+MAX(0,MIN(1,($B$16-F26)/($B$16-$B$17)))*100)/2) -> 17.842262 | M26: =IF(COUNT(H26:J26)=3,AVERAGE(H26:J26),"") -> 23.333333 | N26: =IF(G26="","",G26) -> 51 | O26: =(K26="")+(L26="")+(M26="")+(N26="") -> 0 | P26: =IF(O26=0,"Complete",IF(O26=1,"Partial - 1 pillar defaulted","Limited - "&O26&" pillars defaulted")) -> Complete | Q26: =$B$5*IF(K26="",$B$18,K26)+$B$6*IF(L26="",$B$18,L26)+$B$7*IF(M26="",$B$18,M26)+$B$8*IF(N26="",$B$18,N26) -> 26.785565 | R26: =IF(INDEX('Supplier Universe & Risk'!$U$4:$U$33,MATCH($A26,'Supplier Universe & Risk'!$A$4:$A$33,0))="","",INDEX('Supplier Universe & Risk'!$U$4:$U$33,MATCH($A26,'Supplier Universe & Risk'!$A$4:$A$33,0))) -> 49.7 | S26: =IF(INDEX('Supplier Universe & Risk'!$V$4:$V$33,MATCH($A26,'Supplier Universe & Risk'!$A$4:$A$33,0))="","",INDEX('Supplier Universe & Risk'!$V$4:$V$33,MATCH($A26,'Supplier Universe & Risk'!$A$4:$A$33,0))) -> MEDIUM | T26: =R26-Q26 -> 22.914435 | U26: =RANK(R26,$R$23:$R$46) -> 19 | V26: =RANK(Q26,$Q$23:$Q$46) -> 22
A27: ORG-786 | B27: Estuary Thermal Systems Ltd. | C27: =IF(INDEX('Supplier Universe & Risk'!$M$4:$M$33,MATCH($A27,'Supplier Universe & Risk'!$A$4:$A$33,0))="","",INDEX('Supplier Universe & Risk'!$M$4:$M$33,MATCH($A27,'Supplier Universe & Risk'!$A$4:$A$33,0))) -> 2.53 | D27: =IF(INDEX('Supplier Universe & Risk'!$N$4:$N$33,MATCH($A27,'Supplier Universe & Risk'!$A$4:$A$33,0))="","",INDEX('Supplier Universe & Risk'!$N$4:$N$33,MATCH($A27,'Supplier Universe & Risk'!$A$4:$A$33,0))) -> 2.67 | E27: =IF(INDEX('Supplier Universe & Risk'!$O$4:$O$33,MATCH($A27,'Supplier Universe & Risk'!$A$4:$A$33,0))="","",INDEX('Supplier Universe & Risk'!$O$4:$O$33,MATCH($A27,'Supplier Universe & Risk'!$A$4:$A$33,0))) -> 89.7 | F27: =IF(INDEX('Supplier Universe & Risk'!$P$4:$P$33,MATCH($A27,'Supplier Universe & Risk'!$A$4:$A$33,0))="","",INDEX('Supplier Universe & Risk'!$P$4:$P$33,MATCH($A27,'Supplier Universe & Risk'!$A$4:$A$33,0))) -> 1.8 | G27: =IF(INDEX('Supplier Universe & Risk'!$Q$4:$Q$33,MATCH($A27,'Supplier Universe & Risk'!$A$4:$A$33,0))="","",INDEX('Supplier Universe & Risk'!$Q$4:$Q$33,MATCH($A27,'Supplier Universe & Risk'!$A$4:$A$33,0))) -> 60 | H27: =IF(INDEX('Supplier Universe & Risk'!$R$4:$R$33,MATCH($A27,'Supplier Universe & Risk'!$A$4:$A$33,0))="","",INDEX('Supplier Universe & Risk'!$R$4:$R$33,MATCH($A27,'Supplier Universe & Risk'!$A$4:$A$33,0))) -> 67 | I27: =IF(INDEX('Supplier Universe & Risk'!$S$4:$S$33,MATCH($A27,'Supplier Universe & Risk'!$A$4:$A$33,0))="","",INDEX('Supplier Universe & Risk'!$S$4:$S$33,MATCH($A27,'Supplier Universe & Risk'!$A$4:$A$33,0))) -> 59 | J27: =IF(INDEX('Supplier Universe & Risk'!$T$4:$T$33,MATCH($A27,'Supplier Universe & Risk'!$A$4:$A$33,0))="","",INDEX('Supplier Universe & Risk'!$T$4:$T$33,MATCH($A27,'Supplier Universe & Risk'!$A$4:$A$33,0))) -> 54 | K27: =IF(OR(C27="",D27=""),"",(MAX(0,MIN(1,($B$10-C27)/($B$10-$B$11)))*100+MAX(0,MIN(1,(D27-$B$12)/($B$13-$B$12)))*100)/2) -> 13.916667 | L27: =IF(OR(E27="",F27=""),"",(MAX(0,MIN(1,($B$14-E27)/($B$14-$B$15)))*100+MAX(0,MIN(1,($B$16-F27)/($B$16-$B$17)))*100)/2) -> 10.044643 | M27: =IF(COUNT(H27:J27)=3,AVERAGE(H27:J27),"") -> 60 | N27: =IF(G27="","",G27) -> 60 | O27: =(K27="")+(L27="")+(M27="")+(N27="") -> 0 | P27: =IF(O27=0,"Complete",IF(O27=1,"Partial - 1 pillar defaulted","Limited - "&O27&" pillars defaulted")) -> Complete | Q27: =$B$5*IF(K27="",$B$18,K27)+$B$6*IF(L27="",$B$18,L27)+$B$7*IF(M27="",$B$18,M27)+$B$8*IF(N27="",$B$18,N27) -> 33.686161 | R27: =IF(INDEX('Supplier Universe & Risk'!$U$4:$U$33,MATCH($A27,'Supplier Universe & Risk'!$A$4:$A$33,0))="","",INDEX('Supplier Universe & Risk'!$U$4:$U$33,MATCH($A27,'Supplier Universe & Risk'!$A$4:$A$33,0))) -> 48.4 | S27: =IF(INDEX('Supplier Universe & Risk'!$V$4:$V$33,MATCH($A27,'Supplier Universe & Risk'!$A$4:$A$33,0))="","",INDEX('Supplier Universe & Risk'!$V$4:$V$33,MATCH($A27,'Supplier Universe & Risk'!$A$4:$A$33,0))) -> MEDIUM | T27: =R27-Q27 -> 14.713839 | U27: =RANK(R27,$R$23:$R$46) -> 20 | V27: =RANK(Q27,$Q$23:$Q$46) -> 18
A28: ORG-287 | B28: ForgeLine Enclosures Ltd. | C28: =IF(INDEX('Supplier Universe & Risk'!$M$4:$M$33,MATCH($A28,'Supplier Universe & Risk'!$A$4:$A$33,0))="","",INDEX('Supplier Universe & Risk'!$M$4:$M$33,MATCH($A28,'Supplier Universe & Risk'!$A$4:$A$33,0))) -> 1.94 | D28: =IF(INDEX('Supplier Universe & Risk'!$N$4:$N$33,MATCH($A28,'Supplier Universe & Risk'!$A$4:$A$33,0))="","",INDEX('Supplier Universe & Risk'!$N$4:$N$33,MATCH($A28,'Supplier Universe & Risk'!$A$4:$A$33,0))) -> 3.67 | E28: =IF(INDEX('Supplier Universe & Risk'!$O$4:$O$33,MATCH($A28,'Supplier Universe & Risk'!$A$4:$A$33,0))="","",INDEX('Supplier Universe & Risk'!$O$4:$O$33,MATCH($A28,'Supplier Universe & Risk'!$A$4:$A$33,0))) -> 89.8 | F28: =IF(INDEX('Supplier Universe & Risk'!$P$4:$P$33,MATCH($A28,'Supplier Universe & Risk'!$A$4:$A$33,0))="","",INDEX('Supplier Universe & Risk'!$P$4:$P$33,MATCH($A28,'Supplier Universe & Risk'!$A$4:$A$33,0))) -> -0.3 | G28: =IF(INDEX('Supplier Universe & Risk'!$Q$4:$Q$33,MATCH($A28,'Supplier Universe & Risk'!$A$4:$A$33,0))="","",INDEX('Supplier Universe & Risk'!$Q$4:$Q$33,MATCH($A28,'Supplier Universe & Risk'!$A$4:$A$33,0))) -> 69 | H28: =IF(INDEX('Supplier Universe & Risk'!$R$4:$R$33,MATCH($A28,'Supplier Universe & Risk'!$A$4:$A$33,0))="","",INDEX('Supplier Universe & Risk'!$R$4:$R$33,MATCH($A28,'Supplier Universe & Risk'!$A$4:$A$33,0))) -> 27 | I28: =IF(INDEX('Supplier Universe & Risk'!$S$4:$S$33,MATCH($A28,'Supplier Universe & Risk'!$A$4:$A$33,0))="","",INDEX('Supplier Universe & Risk'!$S$4:$S$33,MATCH($A28,'Supplier Universe & Risk'!$A$4:$A$33,0))) -> 30 | J28: =IF(INDEX('Supplier Universe & Risk'!$T$4:$T$33,MATCH($A28,'Supplier Universe & Risk'!$A$4:$A$33,0))="","",INDEX('Supplier Universe & Risk'!$T$4:$T$33,MATCH($A28,'Supplier Universe & Risk'!$A$4:$A$33,0))) -> 24 | K28: =IF(OR(C28="",D28=""),"",(MAX(0,MIN(1,($B$10-C28)/($B$10-$B$11)))*100+MAX(0,MIN(1,(D28-$B$12)/($B$13-$B$12)))*100)/2) -> 38.720588 | L28: =IF(OR(E28="",F28=""),"",(MAX(0,MIN(1,($B$14-E28)/($B$14-$B$15)))*100+MAX(0,MIN(1,($B$16-F28)/($B$16-$B$17)))*100)/2) -> 14.732143 | M28: =IF(COUNT(H28:J28)=3,AVERAGE(H28:J28),"") -> 27 | N28: =IF(G28="","",G28) -> 69 | O28: =(K28="")+(L28="")+(M28="")+(N28="") -> 0 | P28: =IF(O28=0,"Complete",IF(O28=1,"Partial - 1 pillar defaulted","Limited - "&O28&" pillars defaulted")) -> Complete | Q28: =$B$5*IF(K28="",$B$18,K28)+$B$6*IF(L28="",$B$18,L28)+$B$7*IF(M28="",$B$18,M28)+$B$8*IF(N28="",$B$18,N28) -> 33.749212 | R28: =IF(INDEX('Supplier Universe & Risk'!$U$4:$U$33,MATCH($A28,'Supplier Universe & Risk'!$A$4:$A$33,0))="","",INDEX('Supplier Universe & Risk'!$U$4:$U$33,MATCH($A28,'Supplier Universe & Risk'!$A$4:$A$33,0))) -> 45.4 | S28: =IF(INDEX('Supplier Universe & Risk'!$V$4:$V$33,MATCH($A28,'Supplier Universe & Risk'!$A$4:$A$33,0))="","",INDEX('Supplier Universe & Risk'!$V$4:$V$33,MATCH($A28,'Supplier Universe & Risk'!$A$4:$A$33,0))) -> MEDIUM | T28: =R28-Q28 -> 11.650788 | U28: =RANK(R28,$R$23:$R$46) -> 21 | V28: =RANK(Q28,$Q$23:$Q$46) -> 17
A29: ORG-103 | B29: Grove Battery Controls Ltd. | C29: =IF(INDEX('Supplier Universe & Risk'!$M$4:$M$33,MATCH($A29,'Supplier Universe & Risk'!$A$4:$A$33,0))="","",INDEX('Supplier Universe & Risk'!$M$4:$M$33,MATCH($A29,'Supplier Universe & Risk'!$A$4:$A$33,0))) -> 1.51 | D29: =IF(INDEX('Supplier Universe & Risk'!$N$4:$N$33,MATCH($A29,'Supplier Universe & Risk'!$A$4:$A$33,0))="","",INDEX('Supplier Universe & Risk'!$N$4:$N$33,MATCH($A29,'Supplier Universe & Risk'!$A$4:$A$33,0))) -> 1.33 | E29: =IF(INDEX('Supplier Universe & Risk'!$O$4:$O$33,MATCH($A29,'Supplier Universe & Risk'!$A$4:$A$33,0))="","",INDEX('Supplier Universe & Risk'!$O$4:$O$33,MATCH($A29,'Supplier Universe & Risk'!$A$4:$A$33,0))) -> 78.8 | F29: =IF(INDEX('Supplier Universe & Risk'!$P$4:$P$33,MATCH($A29,'Supplier Universe & Risk'!$A$4:$A$33,0))="","",INDEX('Supplier Universe & Risk'!$P$4:$P$33,MATCH($A29,'Supplier Universe & Risk'!$A$4:$A$33,0))) -> -0.9 | G29: =IF(INDEX('Supplier Universe & Risk'!$Q$4:$Q$33,MATCH($A29,'Supplier Universe & Risk'!$A$4:$A$33,0))="","",INDEX('Supplier Universe & Risk'!$Q$4:$Q$33,MATCH($A29,'Supplier Universe & Risk'!$A$4:$A$33,0))) -> 18 | H29: =IF(INDEX('Supplier Universe & Risk'!$R$4:$R$33,MATCH($A29,'Supplier Universe & Risk'!$A$4:$A$33,0))="","",INDEX('Supplier Universe & Risk'!$R$4:$R$33,MATCH($A29,'Supplier Universe & Risk'!$A$4:$A$33,0))) -> 58 | I29: =IF(INDEX('Supplier Universe & Risk'!$S$4:$S$33,MATCH($A29,'Supplier Universe & Risk'!$A$4:$A$33,0))="","",INDEX('Supplier Universe & Risk'!$S$4:$S$33,MATCH($A29,'Supplier Universe & Risk'!$A$4:$A$33,0))) -> 62 | J29: =IF(INDEX('Supplier Universe & Risk'!$T$4:$T$33,MATCH($A29,'Supplier Universe & Risk'!$A$4:$A$33,0))="","",INDEX('Supplier Universe & Risk'!$T$4:$T$33,MATCH($A29,'Supplier Universe & Risk'!$A$4:$A$33,0))) -> 52 | K29: =IF(OR(C29="",D29=""),"",(MAX(0,MIN(1,($B$10-C29)/($B$10-$B$11)))*100+MAX(0,MIN(1,(D29-$B$12)/($B$13-$B$12)))*100)/2) -> 31.867647 | L29: =IF(OR(E29="",F29=""),"",(MAX(0,MIN(1,($B$14-E29)/($B$14-$B$15)))*100+MAX(0,MIN(1,($B$16-F29)/($B$16-$B$17)))*100)/2) -> 50.535714 | M29: =IF(COUNT(H29:J29)=3,AVERAGE(H29:J29),"") -> 57.333333 | N29: =IF(G29="","",G29) -> 18 | O29: =(K29="")+(L29="")+(M29="")+(N29="") -> 0 | P29: =IF(O29=0,"Complete",IF(O29=1,"Partial - 1 pillar defaulted","Limited - "&O29&" pillars defaulted")) -> Complete | Q29: =$B$5*IF(K29="",$B$18,K29)+$B$6*IF(L29="",$B$18,L29)+$B$7*IF(M29="",$B$18,M29)+$B$8*IF(N29="",$B$18,N29) -> 42.094223 | R29: =IF(INDEX('Supplier Universe & Risk'!$U$4:$U$33,MATCH($A29,'Supplier Universe & Risk'!$A$4:$A$33,0))="","",INDEX('Supplier Universe & Risk'!$U$4:$U$33,MATCH($A29,'Supplier Universe & Risk'!$A$4:$A$33,0))) -> 44.6 | S29: =IF(INDEX('Supplier Universe & Risk'!$V$4:$V$33,MATCH($A29,'Supplier Universe & Risk'!$A$4:$A$33,0))="","",INDEX('Supplier Universe & Risk'!$V$4:$V$33,MATCH($A29,'Supplier Universe & Risk'!$A$4:$A$33,0))) -> LOW | T29: =R29-Q29 -> 2.5057773 | U29: =RANK(R29,$R$23:$R$46) -> 22 | V29: =RANK(Q29,$Q$23:$Q$46) -> 14
A30: ORG-176 | B30: HarborSense Electronics Ltd. | C30: =IF(INDEX('Supplier Universe & Risk'!$M$4:$M$33,MATCH($A30,'Supplier Universe & Risk'!$A$4:$A$33,0))="","",INDEX('Supplier Universe & Risk'!$M$4:$M$33,MATCH($A30,'Supplier Universe & Risk'!$A$4:$A$33,0))) -> 2.24 | D30: =IF(INDEX('Supplier Universe & Risk'!$N$4:$N$33,MATCH($A30,'Supplier Universe & Risk'!$A$4:$A$33,0))="","",INDEX('Supplier Universe & Risk'!$N$4:$N$33,MATCH($A30,'Supplier Universe & Risk'!$A$4:$A$33,0))) -> 2.33 | E30: =IF(INDEX('Supplier Universe & Risk'!$O$4:$O$33,MATCH($A30,'Supplier Universe & Risk'!$A$4:$A$33,0))="","",INDEX('Supplier Universe & Risk'!$O$4:$O$33,MATCH($A30,'Supplier Universe & Risk'!$A$4:$A$33,0))) -> 81.9 | F30: =IF(INDEX('Supplier Universe & Risk'!$P$4:$P$33,MATCH($A30,'Supplier Universe & Risk'!$A$4:$A$33,0))="","",INDEX('Supplier Universe & Risk'!$P$4:$P$33,MATCH($A30,'Supplier Universe & Risk'!$A$4:$A$33,0))) -> -0.9 | G30: =IF(INDEX('Supplier Universe & Risk'!$Q$4:$Q$33,MATCH($A30,'Supplier Universe & Risk'!$A$4:$A$33,0))="","",INDEX('Supplier Universe & Risk'!$Q$4:$Q$33,MATCH($A30,'Supplier Universe & Risk'!$A$4:$A$33,0))) -> 27 | H30: =IF(INDEX('Supplier Universe & Risk'!$R$4:$R$33,MATCH($A30,'Supplier Universe & Risk'!$A$4:$A$33,0))="","",INDEX('Supplier Universe & Risk'!$R$4:$R$33,MATCH($A30,'Supplier Universe & Risk'!$A$4:$A$33,0))) -> 31 | I30: =IF(INDEX('Supplier Universe & Risk'!$S$4:$S$33,MATCH($A30,'Supplier Universe & Risk'!$A$4:$A$33,0))="","",INDEX('Supplier Universe & Risk'!$S$4:$S$33,MATCH($A30,'Supplier Universe & Risk'!$A$4:$A$33,0))) -> 23 | J30: =IF(INDEX('Supplier Universe & Risk'!$T$4:$T$33,MATCH($A30,'Supplier Universe & Risk'!$A$4:$A$33,0))="","",INDEX('Supplier Universe & Risk'!$T$4:$T$33,MATCH($A30,'Supplier Universe & Risk'!$A$4:$A$33,0))) -> 19 | K30: =IF(OR(C30="",D30=""),"",(MAX(0,MIN(1,($B$10-C30)/($B$10-$B$11)))*100+MAX(0,MIN(1,(D30-$B$12)/($B$13-$B$12)))*100)/2) -> 18.730392 | L30: =IF(OR(E30="",F30=""),"",(MAX(0,MIN(1,($B$14-E30)/($B$14-$B$15)))*100+MAX(0,MIN(1,($B$16-F30)/($B$16-$B$17)))*100)/2) -> 40.848214 | M30: =IF(COUNT(H30:J30)=3,AVERAGE(H30:J30),"") -> 24.333333 | N30: =IF(G30="","",G30) -> 27 | O30: =(K30="")+(L30="")+(M30="")+(N30="") -> 0 | P30: =IF(O30=0,"Complete",IF(O30=1,"Partial - 1 pillar defaulted","Limited - "&O30&" pillars defaulted")) -> Complete | Q30: =$B$5*IF(K30="",$B$18,K30)+$B$6*IF(L30="",$B$18,L30)+$B$7*IF(M30="",$B$18,M30)+$B$8*IF(N30="",$B$18,N30) -> 27.181171 | R30: =IF(INDEX('Supplier Universe & Risk'!$U$4:$U$33,MATCH($A30,'Supplier Universe & Risk'!$A$4:$A$33,0))="","",INDEX('Supplier Universe & Risk'!$U$4:$U$33,MATCH($A30,'Supplier Universe & Risk'!$A$4:$A$33,0))) -> 32.5 | S30: =IF(INDEX('Supplier Universe & Risk'!$V$4:$V$33,MATCH($A30,'Supplier Universe & Risk'!$A$4:$A$33,0))="","",INDEX('Supplier Universe & Risk'!$V$4:$V$33,MATCH($A30,'Supplier Universe & Risk'!$A$4:$A$33,0))) -> LOW | T30: =R30-Q30 -> 5.3188288 | U30: =RANK(R30,$R$23:$R$46) -> 24 | V30: =RANK(Q30,$Q$23:$Q$46) -> 21
A31: ORG-439 | B31: IonPeak Semiconductor Ltd. | C31: =IF(INDEX('Supplier Universe & Risk'!$M$4:$M$33,MATCH($A31,'Supplier Universe & Risk'!$A$4:$A$33,0))="","",INDEX('Supplier Universe & Risk'!$M$4:$M$33,MATCH($A31,'Supplier Universe & Risk'!$A$4:$A$33,0))) -> 1.8 | D31: =IF(INDEX('Supplier Universe & Risk'!$N$4:$N$33,MATCH($A31,'Supplier Universe & Risk'!$A$4:$A$33,0))="","",INDEX('Supplier Universe & Risk'!$N$4:$N$33,MATCH($A31,'Supplier Universe & Risk'!$A$4:$A$33,0))) -> 2.4 | E31: =IF(INDEX('Supplier Universe & Risk'!$O$4:$O$33,MATCH($A31,'Supplier Universe & Risk'!$A$4:$A$33,0))="","",INDEX('Supplier Universe & Risk'!$O$4:$O$33,MATCH($A31,'Supplier Universe & Risk'!$A$4:$A$33,0))) -> 85.2 | F31: =IF(INDEX('Supplier Universe & Risk'!$P$4:$P$33,MATCH($A31,'Supplier Universe & Risk'!$A$4:$A$33,0))="","",INDEX('Supplier Universe & Risk'!$P$4:$P$33,MATCH($A31,'Supplier Universe & Risk'!$A$4:$A$33,0))) -> -8.8 | G31: =IF(INDEX('Supplier Universe & Risk'!$Q$4:$Q$33,MATCH($A31,'Supplier Universe & Risk'!$A$4:$A$33,0))="","",INDEX('Supplier Universe & Risk'!$Q$4:$Q$33,MATCH($A31,'Supplier Universe & Risk'!$A$4:$A$33,0))) -> 36 | H31: =IF(INDEX('Supplier Universe & Risk'!$R$4:$R$33,MATCH($A31,'Supplier Universe & Risk'!$A$4:$A$33,0))="","",INDEX('Supplier Universe & Risk'!$R$4:$R$33,MATCH($A31,'Supplier Universe & Risk'!$A$4:$A$33,0))) -> 82 | I31: =IF(INDEX('Supplier Universe & Risk'!$S$4:$S$33,MATCH($A31,'Supplier Universe & Risk'!$A$4:$A$33,0))="","",INDEX('Supplier Universe & Risk'!$S$4:$S$33,MATCH($A31,'Supplier Universe & Risk'!$A$4:$A$33,0))) -> 76 | J31: =IF(INDEX('Supplier Universe & Risk'!$T$4:$T$33,MATCH($A31,'Supplier Universe & Risk'!$A$4:$A$33,0))="","",INDEX('Supplier Universe & Risk'!$T$4:$T$33,MATCH($A31,'Supplier Universe & Risk'!$A$4:$A$33,0))) -> 71 | K31: =IF(OR(C31="",D31=""),"",(MAX(0,MIN(1,($B$10-C31)/($B$10-$B$11)))*100+MAX(0,MIN(1,(D31-$B$12)/($B$13-$B$12)))*100)/2) -> 32.254902 | L31: =IF(OR(E31="",F31=""),"",(MAX(0,MIN(1,($B$14-E31)/($B$14-$B$15)))*100+MAX(0,MIN(1,($B$16-F31)/($B$16-$B$17)))*100)/2) -> 49.345238 | M31: =IF(COUNT(H31:J31)=3,AVERAGE(H31:J31),"") -> 76.333333 | N31: =IF(G31="","",G31) -> 36 | O31: =(K31="")+(L31="")+(M31="")+(N31="") -> 0 | P31: =IF(O31=0,"Complete",IF(O31=1,"Partial - 1 pillar defaulted","Limited - "&O31&" pillars defaulted")) -> Complete | Q31: =$B$5*IF(K31="",$B$18,K31)+$B$6*IF(L31="",$B$18,L31)+$B$7*IF(M31="",$B$18,M31)+$B$8*IF(N31="",$B$18,N31) -> 50.31278 | R31: =IF(INDEX('Supplier Universe & Risk'!$U$4:$U$33,MATCH($A31,'Supplier Universe & Risk'!$A$4:$A$33,0))="","",INDEX('Supplier Universe & Risk'!$U$4:$U$33,MATCH($A31,'Supplier Universe & Risk'!$A$4:$A$33,0))) -> 79 | S31: =IF(INDEX('Supplier Universe & Risk'!$V$4:$V$33,MATCH($A31,'Supplier Universe & Risk'!$A$4:$A$33,0))="","",INDEX('Supplier Universe & Risk'!$V$4:$V$33,MATCH($A31,'Supplier Universe & Risk'!$A$4:$A$33,0))) -> CRITICAL | T31: =R31-Q31 -> 28.68722 | U31: =RANK(R31,$R$23:$R$46) -> 2 | V31: =RANK(Q31,$Q$23:$Q$46) -> 5
A32: ORG-453 | B32: Jade Printed Circuits Ltd. | C32: =IF(INDEX('Supplier Universe & Risk'!$M$4:$M$33,MATCH($A32,'Supplier Universe & Risk'!$A$4:$A$33,0))="","",INDEX('Supplier Universe & Risk'!$M$4:$M$33,MATCH($A32,'Supplier Universe & Risk'!$A$4:$A$33,0))) -> 1.55 | D32: =IF(INDEX('Supplier Universe & Risk'!$N$4:$N$33,MATCH($A32,'Supplier Universe & Risk'!$A$4:$A$33,0))="","",INDEX('Supplier Universe & Risk'!$N$4:$N$33,MATCH($A32,'Supplier Universe & Risk'!$A$4:$A$33,0))) -> 3.1 | E32: =IF(INDEX('Supplier Universe & Risk'!$O$4:$O$33,MATCH($A32,'Supplier Universe & Risk'!$A$4:$A$33,0))="","",INDEX('Supplier Universe & Risk'!$O$4:$O$33,MATCH($A32,'Supplier Universe & Risk'!$A$4:$A$33,0))) -> 86.6 | F32: =IF(INDEX('Supplier Universe & Risk'!$P$4:$P$33,MATCH($A32,'Supplier Universe & Risk'!$A$4:$A$33,0))="","",INDEX('Supplier Universe & Risk'!$P$4:$P$33,MATCH($A32,'Supplier Universe & Risk'!$A$4:$A$33,0))) -> -6.4 | G32: =IF(INDEX('Supplier Universe & Risk'!$Q$4:$Q$33,MATCH($A32,'Supplier Universe & Risk'!$A$4:$A$33,0))="","",INDEX('Supplier Universe & Risk'!$Q$4:$Q$33,MATCH($A32,'Supplier Universe & Risk'!$A$4:$A$33,0))) -> 45 | H32: =IF(INDEX('Supplier Universe & Risk'!$R$4:$R$33,MATCH($A32,'Supplier Universe & Risk'!$A$4:$A$33,0))="","",INDEX('Supplier Universe & Risk'!$R$4:$R$33,MATCH($A32,'Supplier Universe & Risk'!$A$4:$A$33,0))) -> 82 | I32: =IF(INDEX('Supplier Universe & Risk'!$S$4:$S$33,MATCH($A32,'Supplier Universe & Risk'!$A$4:$A$33,0))="","",INDEX('Supplier Universe & Risk'!$S$4:$S$33,MATCH($A32,'Supplier Universe & Risk'!$A$4:$A$33,0))) -> 76 | J32: =IF(INDEX('Supplier Universe & Risk'!$T$4:$T$33,MATCH($A32,'Supplier Universe & Risk'!$A$4:$A$33,0))="","",INDEX('Supplier Universe & Risk'!$T$4:$T$33,MATCH($A32,'Supplier Universe & Risk'!$A$4:$A$33,0))) -> 71 | K32: =IF(OR(C32="",D32=""),"",(MAX(0,MIN(1,($B$10-C32)/($B$10-$B$11)))*100+MAX(0,MIN(1,(D32-$B$12)/($B$13-$B$12)))*100)/2) -> 45.441176 | L32: =IF(OR(E32="",F32=""),"",(MAX(0,MIN(1,($B$14-E32)/($B$14-$B$15)))*100+MAX(0,MIN(1,($B$16-F32)/($B$16-$B$17)))*100)/2) -> 39.255952 | M32: =IF(COUNT(H32:J32)=3,AVERAGE(H32:J32),"") -> 76.333333 | N32: =IF(G32="","",G32) -> 45 | O32: =(K32="")+(L32="")+(M32="")+(N32="") -> 0 | P32: =IF(O32=0,"Complete",IF(O32=1,"Partial - 1 pillar defaulted","Limited - "&O32&" pillars defaulted")) -> Complete | Q32: =$B$5*IF(K32="",$B$18,K32)+$B$6*IF(L32="",$B$18,L32)+$B$7*IF(M32="",$B$18,M32)+$B$8*IF(N32="",$B$18,N32) -> 53.096341 | R32: =IF(INDEX('Supplier Universe & Risk'!$U$4:$U$33,MATCH($A32,'Supplier Universe & Risk'!$A$4:$A$33,0))="","",INDEX('Supplier Universe & Risk'!$U$4:$U$33,MATCH($A32,'Supplier Universe & Risk'!$A$4:$A$33,0))) -> 79 | S32: =IF(INDEX('Supplier Universe & Risk'!$V$4:$V$33,MATCH($A32,'Supplier Universe & Risk'!$A$4:$A$33,0))="","",INDEX('Supplier Universe & Risk'!$V$4:$V$33,MATCH($A32,'Supplier Universe & Risk'!$A$4:$A$33,0))) -> CRITICAL | T32: =R32-Q32 -> 25.903659 | U32: =RANK(R32,$R$23:$R$46) -> 2 | V32: =RANK(Q32,$Q$23:$Q$46) -> 4
A33: ORG-728 | B33: Kestrel Microdevices Ltd. | C33: =IF(INDEX('Supplier Universe & Risk'!$M$4:$M$33,MATCH($A33,'Supplier Universe & Risk'!$A$4:$A$33,0))="","",INDEX('Supplier Universe & Risk'!$M$4:$M$33,MATCH($A33,'Supplier Universe & Risk'!$A$4:$A$33,0))) -> 1.86 | D33: =IF(INDEX('Supplier Universe & Risk'!$N$4:$N$33,MATCH($A33,'Supplier Universe & Risk'!$A$4:$A$33,0))="","",INDEX('Supplier Universe & Risk'!$N$4:$N$33,MATCH($A33,'Supplier Universe & Risk'!$A$4:$A$33,0))) -> 2 | E33: =IF(INDEX('Supplier Universe & Risk'!$O$4:$O$33,MATCH($A33,'Supplier Universe & Risk'!$A$4:$A$33,0))="","",INDEX('Supplier Universe & Risk'!$O$4:$O$33,MATCH($A33,'Supplier Universe & Risk'!$A$4:$A$33,0))) -> 87.3 | F33: =IF(INDEX('Supplier Universe & Risk'!$P$4:$P$33,MATCH($A33,'Supplier Universe & Risk'!$A$4:$A$33,0))="","",INDEX('Supplier Universe & Risk'!$P$4:$P$33,MATCH($A33,'Supplier Universe & Risk'!$A$4:$A$33,0))) -> 1.6 | G33: =IF(INDEX('Supplier Universe & Risk'!$Q$4:$Q$33,MATCH($A33,'Supplier Universe & Risk'!$A$4:$A$33,0))="","",INDEX('Supplier Universe & Risk'!$Q$4:$Q$33,MATCH($A33,'Supplier Universe & Risk'!$A$4:$A$33,0))) -> 54 | H33: =IF(INDEX('Supplier Universe & Risk'!$R$4:$R$33,MATCH($A33,'Supplier Universe & Risk'!$A$4:$A$33,0))="","",INDEX('Supplier Universe & Risk'!$R$4:$R$33,MATCH($A33,'Supplier Universe & Risk'!$A$4:$A$33,0))) -> 31 | I33: =IF(INDEX('Supplier Universe & Risk'!$S$4:$S$33,MATCH($A33,'Supplier Universe & Risk'!$A$4:$A$33,0))="","",INDEX('Supplier Universe & Risk'!$S$4:$S$33,MATCH($A33,'Supplier Universe & Risk'!$A$4:$A$33,0))) -> 23 | J33: =IF(INDEX('Supplier Universe & Risk'!$T$4:$T$33,MATCH($A33,'Supplier Universe & Risk'!$A$4:$A$33,0))="","",INDEX('Supplier Universe & Risk'!$T$4:$T$33,MATCH($A33,'Supplier Universe & Risk'!$A$4:$A$33,0))) -> 19 | K33: =IF(OR(C33="",D33=""),"",(MAX(0,MIN(1,($B$10-C33)/($B$10-$B$11)))*100+MAX(0,MIN(1,(D33-$B$12)/($B$13-$B$12)))*100)/2) -> 27.156863 | L33: =IF(OR(E33="",F33=""),"",(MAX(0,MIN(1,($B$14-E33)/($B$14-$B$15)))*100+MAX(0,MIN(1,($B$16-F33)/($B$16-$B$17)))*100)/2) -> 18.020833 | M33: =IF(COUNT(H33:J33)=3,AVERAGE(H33:J33),"") -> 24.333333 | N33: =IF(G33="","",G33) -> 54 | O33: =(K33="")+(L33="")+(M33="")+(N33="") -> 0 | P33: =IF(O33=0,"Complete",IF(O33=1,"Partial - 1 pillar defaulted","Limited - "&O33&" pillars defaulted")) -> Complete | Q33: =$B$5*IF(K33="",$B$18,K33)+$B$6*IF(L33="",$B$18,L33)+$B$7*IF(M33="",$B$18,M33)+$B$8*IF(N33="",$B$18,N33) -> 28.052267 | R33: =IF(INDEX('Supplier Universe & Risk'!$U$4:$U$33,MATCH($A33,'Supplier Universe & Risk'!$A$4:$A$33,0))="","",INDEX('Supplier Universe & Risk'!$U$4:$U$33,MATCH($A33,'Supplier Universe & Risk'!$A$4:$A$33,0))) -> 57.2 | S33: =IF(INDEX('Supplier Universe & Risk'!$V$4:$V$33,MATCH($A33,'Supplier Universe & Risk'!$A$4:$A$33,0))="","",INDEX('Supplier Universe & Risk'!$V$4:$V$33,MATCH($A33,'Supplier Universe & Risk'!$A$4:$A$33,0))) -> MEDIUM | T33: =R33-Q33 -> 29.147733 | U33: =RANK(R33,$R$23:$R$46) -> 15 | V33: =RANK(Q33,$Q$23:$Q$46) -> 20
A34: ORG-942 | B34: Lumen Magnetics Ltd. | C34: =IF(INDEX('Supplier Universe & Risk'!$M$4:$M$33,MATCH($A34,'Supplier Universe & Risk'!$A$4:$A$33,0))="","",INDEX('Supplier Universe & Risk'!$M$4:$M$33,MATCH($A34,'Supplier Universe & Risk'!$A$4:$A$33,0))) -> 1.37 | D34: =IF(INDEX('Supplier Universe & Risk'!$N$4:$N$33,MATCH($A34,'Supplier Universe & Risk'!$A$4:$A$33,0))="","",INDEX('Supplier Universe & Risk'!$N$4:$N$33,MATCH($A34,'Supplier Universe & Risk'!$A$4:$A$33,0))) -> 3 | E34: =IF(INDEX('Supplier Universe & Risk'!$O$4:$O$33,MATCH($A34,'Supplier Universe & Risk'!$A$4:$A$33,0))="","",INDEX('Supplier Universe & Risk'!$O$4:$O$33,MATCH($A34,'Supplier Universe & Risk'!$A$4:$A$33,0))) -> 89.5 | F34: =IF(INDEX('Supplier Universe & Risk'!$P$4:$P$33,MATCH($A34,'Supplier Universe & Risk'!$A$4:$A$33,0))="","",INDEX('Supplier Universe & Risk'!$P$4:$P$33,MATCH($A34,'Supplier Universe & Risk'!$A$4:$A$33,0))) -> -0.6 | G34: =IF(INDEX('Supplier Universe & Risk'!$Q$4:$Q$33,MATCH($A34,'Supplier Universe & Risk'!$A$4:$A$33,0))="","",INDEX('Supplier Universe & Risk'!$Q$4:$Q$33,MATCH($A34,'Supplier Universe & Risk'!$A$4:$A$33,0))) -> 63 | H34: =IF(INDEX('Supplier Universe & Risk'!$R$4:$R$33,MATCH($A34,'Supplier Universe & Risk'!$A$4:$A$33,0))="","",INDEX('Supplier Universe & Risk'!$R$4:$R$33,MATCH($A34,'Supplier Universe & Risk'!$A$4:$A$33,0))) -> 58 | I34: =IF(INDEX('Supplier Universe & Risk'!$S$4:$S$33,MATCH($A34,'Supplier Universe & Risk'!$A$4:$A$33,0))="","",INDEX('Supplier Universe & Risk'!$S$4:$S$33,MATCH($A34,'Supplier Universe & Risk'!$A$4:$A$33,0))) -> 62 | J34: =IF(INDEX('Supplier Universe & Risk'!$T$4:$T$33,MATCH($A34,'Supplier Universe & Risk'!$A$4:$A$33,0))="","",INDEX('Supplier Universe & Risk'!$T$4:$T$33,MATCH($A34,'Supplier Universe & Risk'!$A$4:$A$33,0))) -> 52 | K34: =IF(OR(C34="",D34=""),"",(MAX(0,MIN(1,($B$10-C34)/($B$10-$B$11)))*100+MAX(0,MIN(1,(D34-$B$12)/($B$13-$B$12)))*100)/2) -> 49.901961 | L34: =IF(OR(E34="",F34=""),"",(MAX(0,MIN(1,($B$14-E34)/($B$14-$B$15)))*100+MAX(0,MIN(1,($B$16-F34)/($B$16-$B$17)))*100)/2) -> 16.383929 | M34: =IF(COUNT(H34:J34)=3,AVERAGE(H34:J34),"") -> 57.333333 | N34: =IF(G34="","",G34) -> 63 | O34: =(K34="")+(L34="")+(M34="")+(N34="") -> 0 | P34: =IF(O34=0,"Complete",IF(O34=1,"Partial - 1 pillar defaulted","Limited - "&O34&" pillars defaulted")) -> Complete | Q34: =$B$5*IF(K34="",$B$18,K34)+$B$6*IF(L34="",$B$18,L34)+$B$7*IF(M34="",$B$18,M34)+$B$8*IF(N34="",$B$18,N34) -> 45.71657 | R34: =IF(INDEX('Supplier Universe & Risk'!$U$4:$U$33,MATCH($A34,'Supplier Universe & Risk'!$A$4:$A$33,0))="","",INDEX('Supplier Universe & Risk'!$U$4:$U$33,MATCH($A34,'Supplier Universe & Risk'!$A$4:$A$33,0))) -> 69.4 | S34: =IF(INDEX('Supplier Universe & Risk'!$V$4:$V$33,MATCH($A34,'Supplier Universe & Risk'!$A$4:$A$33,0))="","",INDEX('Supplier Universe & Risk'!$V$4:$V$33,MATCH($A34,'Supplier Universe & Risk'!$A$4:$A$33,0))) -> HIGH | T34: =R34-Q34 -> 23.68343 | U34: =RANK(R34,$R$23:$R$46) -> 6 | V34: =RANK(Q34,$Q$23:$Q$46) -> 8
